<?xml version="1.0" ?>
<sdf version="1.8">
    <model name='palyarobot'>
      <link name='chassis'>
        <pose>0 0 0 0 0 0</pose>
        <inertial>
          <pose>0 0 0 0 0 0</pose>
          <mass>600</mass>
          <inertia>
            <ixx>3058.224</ixx>
            <ixy>0</ixy>
            <ixz>0</ixz>
            <iyy>10581.777333</iyy>
            <iyz>0</iyz>
            <izz>13427.937333</izz>
          </inertia>
        </inertial>
        <visual name='visual_chassis'>
          <pose>0 0 0 1.570796 0 1.570796</pose>
          <geometry>
            <mesh>
              <uri>model://meshes/Chassis.obj</uri>
            </mesh>
          </geometry>
        </visual>
        <collision name='collision_chassis'>
          <pose>0.3165 0 0 0 0 0</pose>
          <geometry>
            <box>
              <size>1 0.5 0.282</size>
            </box>
          </geometry>
        </collision>
      </link>

      <link name='front_left_wheel'>
        <pose>0.633 0.349 0 -1.570796 0 0</pose>
        <inertial>
          <mass>1</mass>
          <inertia>
            <ixx>7.4413575</ixx>
            <ixy>0</ixy>
            <ixz>0</ixz>
            <iyy>7.4413575</iyy>
            <iyz>0</iyz>
            <izz>13.21938</izz>
          </inertia>
        </inertial>
        <visual name='visual_front_left_wheel'>
          <pose>0 0 0 0 1.570796 0</pose>
          <geometry>
            <mesh>
              <uri>model://meshes/WheelRight.obj</uri>
            </mesh>
          </geometry>
        </visual>
        <collision name='collision_front_left_wheel'>
          <geometry>
            <cylinder>
              <length>0.1</length>
              <radius>0.21</radius>
            </cylinder>
          </geometry>
          <surface>
            <friction>
              <ode>
                <mu>0.5</mu>
                <mu2>1.0</mu2>
                <fdir1>0 0 1</fdir1>
              </ode>
            </friction>
          </surface>
        </collision>
      </link>

      <link name='front_right_wheel'>
        <pose>0.633 -0.349 0 -1.570796 0 0</pose>
        <inertial>
          <mass>90</mass>
          <inertia>
            <ixx>7.4413575</ixx>
            <ixy>0</ixy>
            <ixz>0</ixz>
            <iyy>7.4413575</iyy>
            <iyz>0</iyz>
            <izz>13.21938</izz>
          </inertia>
        </inertial>
        <visual name='visual_front_right_wheel'>
          <pose>0 0 0 0 1.570796 0</pose>
          <geometry>
            <mesh>
              <uri>model://meshes/WheelLeft.obj</uri>
            </mesh>
          </geometry>
        </visual>
        <collision name='collision_front_right_wheel'>
          <geometry>
            <cylinder>
              <length>0.1</length>
              <radius>0.21</radius>
            </cylinder>
          </geometry>
          <surface>
            <friction>
              <ode>
                <mu>0.5</mu>
                <mu2>1.0</mu2>
                <fdir1>0 0 1</fdir1>
              </ode>
            </friction>
          </surface>
        </collision>
      </link>

      <link name='rear_left_wheel'>
        <pose>0 0.349 0 -1.570796 0 0</pose>
        <inertial>
          <mass>90</mass>
          <inertia>
            <ixx>7.4413575</ixx>
            <ixy>0</ixy>
            <ixz>0</ixz>
            <iyy>7.4413575</iyy>
            <iyz>0</iyz>
            <izz>13.21938</izz>
          </inertia>
        </inertial>
        <visual name='visual_rear_left_wheel'>
          <pose>0 0 0 0 1.570796 0</pose>
          <geometry>
            <mesh>
              <uri>model://meshes/WheelRight.obj</uri>
            </mesh>
          </geometry>
        </visual>
        <collision name='collision_rear_left_wheel'>
          <geometry>
            <cylinder>
              <length>0.1</length>
              <radius>0.21</radius>
            </cylinder>
          </geometry>
          <surface>
            <friction>
              <ode>
                <mu>0.5</mu>
                <mu2>1.0</mu2>
                <fdir1>0 0 1</fdir1>
              </ode>
            </friction>
          </surface>
        </collision>
      </link>

      <link name='rear_right_wheel'>
        <pose>0 -0.349 0 -1.570796 0 0</pose>
        <inertial>
          <mass>1</mass>
          <inertia>
            <ixx>7.4413575</ixx>
            <ixy>0</ixy>
            <ixz>0</ixz>
            <iyy>7.4413575</iyy>
            <iyz>0</iyz>
            <izz>13.21938</izz>
          </inertia>
        </inertial>
        <visual name='visual_rear_right_wheel'>
          <pose>0 0 0 0 1.570796 0</pose>
          <geometry>
            <mesh>
              <uri>model://meshes/WheelLeft.obj</uri>
            </mesh>
          </geometry>
        </visual>
        <collision name='collision_rear_right_wheel'>
          <geometry>
            <cylinder>
              <length>0.1</length>
              <radius>0.21</radius>
            </cylinder>
          </geometry>
          <surface>
            <friction>
              <ode>
                <mu>0.5</mu>
                <mu2>1.0</mu2>
                <fdir1>0 0 1</fdir1>
              </ode>
            </friction>
          </surface>
        </collision>
      </link>

       <link name="ouster_link">
        <pose>1.0 0 0.2 0 0.0 0</pose>
        <visual name="visual">
          <geometry>
            <cylinder>
              <length>0.09</length>
              <radius>0.05</radius>
            </cylinder>
          </geometry>
        </visual>
        <sensor name='gpu_lidar' type='gpu_lidar'>
          <topic>/model/gamma/points</topic>
          <update_rate>5</update_rate>
          <ray>
            <scan>
              <horizontal>
                <samples>640</samples>
                <resolution>1</resolution>
                <min_angle>-1.396263</min_angle>
                <max_angle>1.396263</max_angle>
              </horizontal>
              <vertical>
                <samples>16</samples>
                <resolution>1</resolution>
                <min_angle>-1</min_angle>
                <max_angle>1</max_angle>
              </vertical>
            </scan>
            <range>
              <min>0.08</min>
              <max>10.0</max>
              <resolution>0.01</resolution>
            </range>
          </ray>
          <alwaysOn>1</alwaysOn>
          <visualize>true</visualize>
        </sensor>
      </link>

      <joint name="ouster_joint" type="fixed">
        <parent>chassis</parent>
        <child>ouster_link</child>
      </joint>


      <joint name='front_left_wheel_joint' type='revolute'>
        <parent>chassis</parent>
        <child>front_left_wheel</child>
        <axis>
          <xyz>0 0 1</xyz>
          <limit>
            <lower>-1.79769e+308</lower>
            <upper>1.79769e+308</upper>
          </limit>
        </axis>
      </joint>

      <joint name='front_right_wheel_joint' type='revolute'>
        <parent>chassis</parent>
        <child>front_right_wheel</child>
        <axis>
          <xyz>0 0 1</xyz>
          <limit>
            <lower>-1.79769e+308</lower>
            <upper>1.79769e+308</upper>
          </limit>
        </axis>
      </joint>

      <joint name='rear_left_wheel_joint' type='revolute'>
        <parent>chassis</parent>
        <child>rear_left_wheel</child>
        <axis>
          <xyz>0 0 1</xyz>
          <limit>
            <lower>-1.79769e+308</lower>
            <upper>1.79769e+308</upper>
          </limit>
        </axis>
      </joint>

      <joint name='rear_right_wheel_joint' type='revolute'>
        <parent>chassis</parent>
        <child>rear_right_wheel</child>
        <axis>
          <xyz>0 0 1</xyz>
          <limit>
            <lower>-1.79769e+308</lower>
            <upper>1.79769e+308</upper>
          </limit>
        </axis>
      </joint>

      <plugin
        filename="libignition-gazebo-diff-drive-system.so"
        name="ignition::gazebo::systems::DiffDrive">
        <left_joint>front_left_wheel_joint</left_joint>
        <left_joint>rear_left_wheel_joint</left_joint>
        <right_joint>front_right_wheel_joint</right_joint>
        <right_joint>rear_right_wheel_joint</right_joint>
        <wheel_separation>0.698</wheel_separation>
        <wheel_radius>0.21</wheel_radius>
        <odom_publish_frequency>1</odom_publish_frequency>
        <topic>/model/palyarobot/cmd_vel</topic>
      </plugin>
    </model>
</sdf>
